
-- Apple Tree (built column by column, bottom to top)

ethereal.appletree = {
	size = {x=3, y=6, z=3},
	data = {

		-- -1

		{name="ignore", param1=255, param2=0}, -- row 1 (bottom)
		{name="ignore", param1=255, param2=0},
		{name="ignore", param1=255, param2=0},

		{name="ignore", param1=255, param2=0}, -- row 2
		{name="ignore", param1=255, param2=0},
		{name="ignore", param1=255, param2=0},

		{name="ignore", param1=255, param2=0}, -- row 3
		{name="ignore", param1=255, param2=0},
		{name="ignore", param1=255, param2=0},

		{name="default:leaves", param1=223, param2=0}, -- row 4
		{name="default:leaves", param1=223, param2=0},
		{name="default:apple", param1=20, param2=0},

		{name="default:leaves", param1=255, param2=0}, -- row 5
		{name="default:leaves", param1=255, param2=0},
		{name="default:leaves", param1=255, param2=0},
		
		{name="default:leaves", param1=223, param2=0}, -- row 6 (top)
		{name="default:apple", param1=20, param2=0},
		{name="default:leaves", param1=223, param2=0},

		-- 0

		{name="ignore", param1=255, param2=0},
		{name="default:tree", param1=255, param2=0},
		{name="ignore", param1=255, param2=0},

		{name="ignore", param1=255, param2=0},
		{name="default:tree", param1=255, param2=0},
		{name="ignore", param1=255, param2=0},

		{name="ignore", param1=255, param2=0},
		{name="default:tree", param1=255, param2=0},
		{name="ignore", param1=255, param2=8},

		{name="default:leaves", param1=223, param2=0},
		{name="default:tree", param1=255, param2=0},
		{name="default:leaves", param1=223, param2=0},

		{name="default:leaves", param1=255, param2=0},
		{name="default:tree", param1=255, param2=0},
		{name="default:leaves", param1=255, param2=0},
		
		{name="default:leaves", param1=223, param2=0},
		{name="default:leaves", param1=255, param2=0},
		{name="default:leaves", param1=223, param2=0},

		-- 1

		{name="ignore", param1=255, param2=0},
		{name="ignore", param1=255, param2=0},
		{name="ignore", param1=255, param2=0},

		{name="ignore", param1=255, param2=0},
		{name="ignore", param1=255, param2=0},
		{name="ignore", param1=255, param2=0},

		{name="ignore", param1=255, param2=0},
		{name="ignore", param1=255, param2=0},
		{name="ignore", param1=255, param2=0},

		{name="default:apple", param1=20, param2=0},
		{name="default:leaves", param1=223, param2=0},
		{name="default:leaves", param1=223, param2=0},

		{name="default:leaves", param1=255, param2=0},
		{name="default:leaves", param1=255, param2=0},
		{name="default:leaves", param1=255, param2=0},
		
		{name="default:leaves", param1=223, param2=0},
		{name="default:leaves", param1=223, param2=0},
		{name="default:leaves", param1=223, param2=0},

	},
	yslice_prob = {
		{ypos=1, prob=127},
	},
}
