
-- Bamboo Tree (built column by column, bottom to top)

local i = "air"
local t = "ethereal:bamboo"
local l = "ethereal:bamboo_leaves"

ethereal.bambootree = {
	size = {x=3, y=18, z=3},
	data = {

		{name=i, param1=000}, {name=i, param1=000}, {name=i, param1=000},
		{name=i, param1=000}, {name=i, param1=000}, {name=i, param1=000},
		{name=i, param1=000}, {name=i, param1=000}, {name=i, param1=000},
		{name=i, param1=000}, {name=i, param1=000}, {name=i, param1=000},
		{name=i, param1=000}, {name=i, param1=000}, {name=i, param1=000},
		{name=i, param1=000}, {name=i, param1=000}, {name=i, param1=000},
		{name=i, param1=000}, {name=i, param1=000}, {name=i, param1=000},
		{name=i, param1=000}, {name=i, param1=000}, {name=i, param1=000},
		{name=i, param1=000}, {name=i, param1=000}, {name=i, param1=000},
		{name=i, param1=000}, {name=i, param1=000}, {name=i, param1=000},
		{name=i, param1=000}, {name=i, param1=000}, {name=i, param1=000},
		{name=i, param1=000}, {name=i, param1=000}, {name=i, param1=000},
		{name=i, param1=000}, {name=i, param1=000}, {name=i, param1=000},
		{name=i, param1=000}, {name=i, param1=000}, {name=i, param1=000},
		{name=i, param1=000}, {name=i, param1=000}, {name=i, param1=000},
		{name=l, param1=100}, {name=l, param1=255}, {name=l, param1=100},
		{name=i, param1=000}, {name=l, param1=255}, {name=i, param1=000},
		{name=i, param1=000}, {name=i, param1=000}, {name=i, param1=000},

		{name=i, param1=000}, {name=t, param1=255}, {name=i, param1=000},
		{name=i, param1=000}, {name=t, param1=255}, {name=i, param1=000},
		{name=i, param1=000}, {name=t, param1=255}, {name=i, param1=000},
		{name=i, param1=000}, {name=t, param1=255}, {name=i, param1=000},
		{name=i, param1=000}, {name=t, param1=255}, {name=i, param1=000},
		{name=i, param1=000}, {name=t, param1=255}, {name=i, param1=000},
		{name=i, param1=000}, {name=t, param1=255}, {name=i, param1=000},
		{name=i, param1=000}, {name=t, param1=255}, {name=i, param1=000},
		{name=i, param1=000}, {name=t, param1=255}, {name=i, param1=000},
		{name=i, param1=000}, {name=t, param1=255}, {name=i, param1=000},
		{name=i, param1=000}, {name=t, param1=255}, {name=i, param1=000},
		{name=i, param1=000}, {name=t, param1=255}, {name=i, param1=000},
		{name=i, param1=000}, {name=t, param1=255}, {name=i, param1=000},
		{name=i, param1=000}, {name=t, param1=255}, {name=i, param1=000},
		{name=i, param1=000}, {name=t, param1=255}, {name=i, param1=000},
		{name=l, param1=100}, {name=l, param1=255}, {name=l, param1=100},
		{name=i, param1=000}, {name=l, param1=255}, {name=i, param1=000},
		{name=i, param1=000}, {name=l, param1=127}, {name=i, param1=000},

		{name=i, param1=000}, {name=i, param1=000}, {name=i, param1=000},
		{name=i, param1=000}, {name=i, param1=000}, {name=i, param1=000},
		{name=i, param1=000}, {name=i, param1=000}, {name=i, param1=000},
		{name=i, param1=000}, {name=i, param1=000}, {name=i, param1=000},
		{name=i, param1=000}, {name=i, param1=000}, {name=i, param1=000},
		{name=i, param1=000}, {name=i, param1=000}, {name=i, param1=000},
		{name=i, param1=000}, {name=i, param1=000}, {name=i, param1=000},
		{name=i, param1=000}, {name=i, param1=000}, {name=i, param1=000},
		{name=i, param1=000}, {name=i, param1=000}, {name=i, param1=000},
		{name=i, param1=000}, {name=i, param1=000}, {name=i, param1=000},
		{name=i, param1=000}, {name=i, param1=000}, {name=i, param1=000},
		{name=i, param1=000}, {name=i, param1=000}, {name=i, param1=000},
		{name=i, param1=000}, {name=i, param1=000}, {name=i, param1=000},
		{name=i, param1=000}, {name=i, param1=000}, {name=i, param1=000},
		{name=i, param1=000}, {name=i, param1=000}, {name=i, param1=000},
		{name=l, param1=100}, {name=l, param1=255}, {name=l, param1=100},
		{name=i, param1=000}, {name=l, param1=255}, {name=i, param1=000},
		{name=i, param1=000}, {name=i, param1=000}, {name=i, param1=000},

	},
	yslice_prob = {
		{ypos=3, prob=127},
	},
}
