
-- Banana Tree (built column by column, bottom to top)

local i = "ignore"
local t = "ethereal:banana_trunk"
local l = "ethereal:bananaleaves"
local b = "ethereal:banana"

ethereal.bananatree = {
	size = {x=7, y=8, z=7},
	data = {

{name=i, param1=255}, {name=i, param1=255}, {name=i, param1=255}, {name=i, param1=255}, {name=i, param1=255}, {name=i, param1=255}, {name=i, param1=255},
{name=i, param1=255}, {name=i, param1=255}, {name=i, param1=255}, {name=i, param1=255}, {name=i, param1=255}, {name=i, param1=255}, {name=i, param1=255},
{name=i, param1=255}, {name=i, param1=255}, {name=i, param1=255}, {name=i, param1=255}, {name=i, param1=255}, {name=i, param1=255}, {name=i, param1=255},
{name=i, param1=255}, {name=i, param1=255}, {name=i, param1=255}, {name=i, param1=255}, {name=i, param1=255}, {name=i, param1=255}, {name=i, param1=255},
{name=i, param1=255}, {name=i, param1=255}, {name=i, param1=255}, {name=i, param1=255}, {name=i, param1=255}, {name=i, param1=255}, {name=i, param1=255},
{name=i, param1=255}, {name=i, param1=255}, {name=i, param1=255}, {name=i, param1=255}, {name=i, param1=255}, {name=i, param1=255}, {name=i, param1=255},
{name=i, param1=255}, {name=i, param1=255}, {name=i, param1=255}, {name=l, param1=180}, {name=i, param1=255}, {name=i, param1=255}, {name=i, param1=255},
{name=i, param1=255}, {name=i, param1=255}, {name=i, param1=255}, {name=l, param1=255}, {name=i, param1=255}, {name=i, param1=255}, {name=i, param1=255},

{name=i, param1=255}, {name=i, param1=255}, {name=i, param1=255}, {name=i, param1=255}, {name=i, param1=255}, {name=i, param1=255}, {name=i, param1=255},
{name=i, param1=255}, {name=i, param1=255}, {name=i, param1=255}, {name=i, param1=255}, {name=i, param1=255}, {name=i, param1=255}, {name=i, param1=255},
{name=i, param1=255}, {name=i, param1=255}, {name=i, param1=255}, {name=i, param1=255}, {name=i, param1=255}, {name=i, param1=255}, {name=i, param1=255},
{name=i, param1=255}, {name=i, param1=255}, {name=i, param1=255}, {name=i, param1=255}, {name=i, param1=255}, {name=i, param1=255}, {name=i, param1=255},
{name=i, param1=255}, {name=i, param1=255}, {name=i, param1=255}, {name=b, param1=070}, {name=i, param1=255}, {name=i, param1=255}, {name=i, param1=255},
{name=i, param1=255}, {name=i, param1=255}, {name=i, param1=255}, {name=b, param1=255}, {name=i, param1=255}, {name=i, param1=255}, {name=i, param1=255},
{name=i, param1=255}, {name=i, param1=255}, {name=i, param1=255}, {name=l, param1=255}, {name=i, param1=255}, {name=i, param1=255}, {name=i, param1=255},
{name=i, param1=255}, {name=i, param1=255}, {name=i, param1=255}, {name=i, param1=255}, {name=i, param1=255}, {name=i, param1=255}, {name=i, param1=255},

{name=i, param1=255}, {name=i, param1=255}, {name=i, param1=255}, {name=i, param1=255}, {name=i, param1=255}, {name=i, param1=255}, {name=i, param1=255},
{name=i, param1=255}, {name=i, param1=255}, {name=i, param1=255}, {name=i, param1=255}, {name=i, param1=255}, {name=i, param1=255}, {name=i, param1=255},
{name=i, param1=255}, {name=i, param1=255}, {name=i, param1=255}, {name=i, param1=255}, {name=i, param1=255}, {name=i, param1=255}, {name=i, param1=255},
{name=i, param1=255}, {name=i, param1=255}, {name=i, param1=255}, {name=i, param1=255}, {name=i, param1=255}, {name=i, param1=255}, {name=i, param1=255},
{name=i, param1=255}, {name=i, param1=255}, {name=b, param1=070}, {name=t, param1=255}, {name=b, param1=070}, {name=i, param1=255}, {name=i, param1=255},
{name=i, param1=255}, {name=i, param1=255}, {name=b, param1=255}, {name=l, param1=255}, {name=b, param1=255}, {name=i, param1=255}, {name=i, param1=255},
{name=i, param1=255}, {name=l, param1=255}, {name=l, param1=255}, {name=l, param1=255}, {name=l, param1=255}, {name=l, param1=255}, {name=i, param1=255},
{name=l, param1=255}, {name=l, param1=180}, {name=i, param1=255}, {name=l, param1=255}, {name=i, param1=255}, {name=l, param1=180}, {name=l, param1=255},

{name=i, param1=255}, {name=i, param1=255}, {name=i, param1=255}, {name=t, param1=255}, {name=i, param1=255}, {name=i, param1=255}, {name=i, param1=255},
{name=i, param1=255}, {name=i, param1=255}, {name=i, param1=255}, {name=t, param1=255}, {name=i, param1=255}, {name=i, param1=255}, {name=i, param1=255},
{name=i, param1=255}, {name=i, param1=255}, {name=i, param1=255}, {name=t, param1=255}, {name=i, param1=255}, {name=i, param1=255}, {name=i, param1=255},
{name=i, param1=255}, {name=i, param1=255}, {name=i, param1=255}, {name=t, param1=255}, {name=i, param1=255}, {name=i, param1=255}, {name=i, param1=255},
{name=i, param1=255}, {name=i, param1=255}, {name=i, param1=255}, {name=b, param1=070}, {name=i, param1=255}, {name=i, param1=255}, {name=i, param1=255},
{name=i, param1=255}, {name=i, param1=255}, {name=i, param1=255}, {name=b, param1=255}, {name=i, param1=255}, {name=i, param1=255}, {name=i, param1=255},
{name=i, param1=255}, {name=i, param1=255}, {name=i, param1=255}, {name=l, param1=255}, {name=i, param1=255}, {name=i, param1=255}, {name=i, param1=255},
{name=i, param1=255}, {name=i, param1=255}, {name=i, param1=255}, {name=i, param1=255}, {name=i, param1=255}, {name=i, param1=255}, {name=i, param1=255},

{name=i, param1=255}, {name=i, param1=255}, {name=i, param1=255}, {name=i, param1=255}, {name=i, param1=255}, {name=i, param1=255}, {name=i, param1=255},
{name=i, param1=255}, {name=i, param1=255}, {name=i, param1=255}, {name=i, param1=255}, {name=i, param1=255}, {name=i, param1=255}, {name=i, param1=255},
{name=i, param1=255}, {name=i, param1=255}, {name=i, param1=255}, {name=i, param1=255}, {name=i, param1=255}, {name=i, param1=255}, {name=i, param1=255},
{name=i, param1=255}, {name=i, param1=255}, {name=i, param1=255}, {name=i, param1=255}, {name=i, param1=255}, {name=i, param1=255}, {name=i, param1=255},
{name=i, param1=255}, {name=i, param1=255}, {name=i, param1=255}, {name=i, param1=255}, {name=i, param1=255}, {name=i, param1=255}, {name=i, param1=255},
{name=i, param1=255}, {name=i, param1=255}, {name=i, param1=255}, {name=i, param1=255}, {name=i, param1=255}, {name=i, param1=255}, {name=i, param1=255},
{name=i, param1=255}, {name=i, param1=255}, {name=i, param1=255}, {name=l, param1=255}, {name=i, param1=255}, {name=i, param1=255}, {name=i, param1=255},
{name=i, param1=255}, {name=i, param1=255}, {name=i, param1=255}, {name=l, param1=180}, {name=i, param1=255}, {name=i, param1=255}, {name=i, param1=255},

{name=i, param1=255}, {name=i, param1=255}, {name=i, param1=255}, {name=i, param1=255}, {name=i, param1=255}, {name=i, param1=255}, {name=i, param1=255},
{name=i, param1=255}, {name=i, param1=255}, {name=i, param1=255}, {name=i, param1=255}, {name=i, param1=255}, {name=i, param1=255}, {name=i, param1=255},
{name=i, param1=255}, {name=i, param1=255}, {name=i, param1=255}, {name=i, param1=255}, {name=i, param1=255}, {name=i, param1=255}, {name=i, param1=255},
{name=i, param1=255}, {name=i, param1=255}, {name=i, param1=255}, {name=i, param1=255}, {name=i, param1=255}, {name=i, param1=255}, {name=i, param1=255},
{name=i, param1=255}, {name=i, param1=255}, {name=i, param1=255}, {name=i, param1=255}, {name=i, param1=255}, {name=i, param1=255}, {name=i, param1=255},
{name=i, param1=255}, {name=i, param1=255}, {name=i, param1=255}, {name=i, param1=255}, {name=i, param1=255}, {name=i, param1=255}, {name=i, param1=255},
{name=i, param1=255}, {name=i, param1=255}, {name=i, param1=255}, {name=i, param1=255}, {name=i, param1=255}, {name=i, param1=255}, {name=i, param1=255},
{name=i, param1=255}, {name=i, param1=255}, {name=i, param1=255}, {name=l, param1=255}, {name=i, param1=255}, {name=i, param1=255}, {name=i, param1=255},

{name=i, param1=255}, {name=i, param1=255}, {name=i, param1=255}, {name=i, param1=255}, {name=i, param1=255}, {name=i, param1=255}, {name=i, param1=255},
{name=i, param1=255}, {name=i, param1=255}, {name=i, param1=255}, {name=i, param1=255}, {name=i, param1=255}, {name=i, param1=255}, {name=i, param1=255},
{name=i, param1=255}, {name=i, param1=255}, {name=i, param1=255}, {name=i, param1=255}, {name=i, param1=255}, {name=i, param1=255}, {name=i, param1=255},
{name=i, param1=255}, {name=i, param1=255}, {name=i, param1=255}, {name=i, param1=255}, {name=i, param1=255}, {name=i, param1=255}, {name=i, param1=255},
{name=i, param1=255}, {name=i, param1=255}, {name=i, param1=255}, {name=i, param1=255}, {name=i, param1=255}, {name=i, param1=255}, {name=i, param1=255},
{name=i, param1=255}, {name=i, param1=255}, {name=i, param1=255}, {name=i, param1=255}, {name=i, param1=255}, {name=i, param1=255}, {name=i, param1=255},
{name=i, param1=255}, {name=i, param1=255}, {name=i, param1=255}, {name=i, param1=255}, {name=i, param1=255}, {name=i, param1=255}, {name=i, param1=255},
{name=i, param1=255}, {name=i, param1=255}, {name=i, param1=255}, {name=i, param1=255}, {name=i, param1=255}, {name=i, param1=255}, {name=i, param1=255},

	},
	yslice_prob = {
		{ypos=1, prob=127},
	},
}
