
-- Birch Tree (built column by column, bottom to top)

local i = "air"
local t = "ethereal:birch_trunk"
local l = "ethereal:birch_leaves"

ethereal.birchtree = {size = {x = 5, y = 7, z = 5}, data = {

{name=i, param1=000}, {name=i, param1=000}, {name=i, param1=000}, {name=i, param1=000}, {name=i, param1=000},
{name=i, param1=000}, {name=i, param1=000}, {name=i, param1=000}, {name=i, param1=000}, {name=i, param1=000},
{name=i, param1=000}, {name=i, param1=000}, {name=i, param1=000}, {name=i, param1=000}, {name=i, param1=000},
{name=l, param1=150}, {name=l, param1=255}, {name=l, param1=255}, {name=l, param1=255}, {name=l, param1=150},
{name=l, param1=150}, {name=l, param1=255}, {name=l, param1=255}, {name=l, param1=255}, {name=l, param1=150},
{name=i, param1=000}, {name=i, param1=000}, {name=i, param1=000}, {name=i, param1=000}, {name=i, param1=000},
{name=i, param1=000}, {name=i, param1=000}, {name=i, param1=000}, {name=i, param1=000}, {name=i, param1=000},

{name=i, param1=000}, {name=i, param1=000}, {name=i, param1=000}, {name=i, param1=000}, {name=i, param1=000},
{name=i, param1=000}, {name=i, param1=000}, {name=i, param1=000}, {name=i, param1=000}, {name=i, param1=000},
{name=i, param1=000}, {name=i, param1=000}, {name=i, param1=000}, {name=i, param1=000}, {name=i, param1=000},
{name=l, param1=255}, {name=l, param1=255}, {name=l, param1=255}, {name=l, param1=255}, {name=l, param1=255},
{name=l, param1=255}, {name=l, param1=255}, {name=l, param1=255}, {name=l, param1=255}, {name=l, param1=255},
{name=i, param1=000}, {name=l, param1=150}, {name=l, param1=255}, {name=l, param1=150}, {name=i, param1=000},
{name=i, param1=000}, {name=i, param1=000}, {name=l, param1=255}, {name=i, param1=000}, {name=i, param1=000},

{name=i, param1=000}, {name=i, param1=000}, {name=t, param1=255}, {name=i, param1=000}, {name=i, param1=000},
{name=i, param1=000}, {name=i, param1=000}, {name=t, param1=255}, {name=i, param1=000}, {name=i, param1=000},
{name=i, param1=000}, {name=i, param1=000}, {name=t, param1=255}, {name=i, param1=000}, {name=i, param1=000},
{name=l, param1=255}, {name=l, param1=255}, {name=t, param1=255}, {name=l, param1=255}, {name=l, param1=255},
{name=l, param1=255}, {name=l, param1=255}, {name=t, param1=255}, {name=l, param1=255}, {name=l, param1=255},
{name=i, param1=000}, {name=l, param1=255}, {name=t, param1=255}, {name=l, param1=255}, {name=i, param1=000},
{name=i, param1=000}, {name=l, param1=255}, {name=l, param1=255}, {name=l, param1=255}, {name=i, param1=000},

{name=i, param1=000}, {name=i, param1=000}, {name=i, param1=000}, {name=i, param1=000}, {name=i, param1=000},
{name=i, param1=000}, {name=i, param1=000}, {name=i, param1=000}, {name=i, param1=000}, {name=i, param1=000},
{name=i, param1=000}, {name=i, param1=000}, {name=i, param1=000}, {name=i, param1=000}, {name=i, param1=000},
{name=l, param1=255}, {name=l, param1=255}, {name=l, param1=255}, {name=l, param1=255}, {name=l, param1=255},
{name=l, param1=255}, {name=l, param1=255}, {name=l, param1=255}, {name=l, param1=255}, {name=l, param1=255},
{name=i, param1=000}, {name=l, param1=150}, {name=l, param1=255}, {name=l, param1=150}, {name=i, param1=000},
{name=i, param1=000}, {name=i, param1=000}, {name=l, param1=255}, {name=i, param1=000}, {name=i, param1=000},

{name=i, param1=000}, {name=i, param1=000}, {name=i, param1=000}, {name=i, param1=000}, {name=i, param1=000},
{name=i, param1=000}, {name=i, param1=000}, {name=i, param1=000}, {name=i, param1=000}, {name=i, param1=000},
{name=i, param1=000}, {name=i, param1=000}, {name=i, param1=000}, {name=i, param1=000}, {name=i, param1=000},
{name=l, param1=150}, {name=l, param1=255}, {name=l, param1=255}, {name=l, param1=255}, {name=l, param1=150},
{name=l, param1=150}, {name=l, param1=255}, {name=l, param1=255}, {name=l, param1=255}, {name=l, param1=150},
{name=i, param1=000}, {name=i, param1=000}, {name=i, param1=000}, {name=i, param1=000}, {name=i, param1=000},
{name=i, param1=000}, {name=i, param1=000}, {name=i, param1=000}, {name=i, param1=000}, {name=i, param1=000},

}, yslice_prob = {{ypos = 1, prob = 127}}}
