
-- Bush (built column by column, bottom to top)

local i = "air"
local b = "ethereal:bush"

ethereal.bush = {
	size = {x=5, y=3, z=5},
	data = {

{name=b, param1=100}, {name=b, param1=255}, {name=b, param1=255}, {name=b, param1=255}, {name=b, param1=100},
{name=i, param1=000}, {name=i, param1=000}, {name=i, param1=000}, {name=i, param1=000}, {name=i, param1=000},
{name=i, param1=000}, {name=i, param1=000}, {name=i, param1=000}, {name=i, param1=000}, {name=i, param1=000},

{name=b, param1=255}, {name=b, param1=255}, {name=b, param1=255}, {name=b, param1=255}, {name=b, param1=255},
{name=i, param1=000}, {name=b, param1=100}, {name=b, param1=255}, {name=b, param1=100}, {name=i, param1=000},
{name=i, param1=000}, {name=i, param1=000}, {name=i, param1=000}, {name=i, param1=000}, {name=i, param1=000},

{name=b, param1=255}, {name=b, param1=255}, {name=b, param1=255}, {name=b, param1=255}, {name=b, param1=255},
{name=i, param1=000}, {name=b, param1=255}, {name=b, param1=255}, {name=b, param1=255}, {name=i, param1=000},
{name=i, param1=000}, {name=i, param1=000}, {name=b, param1=100}, {name=i, param1=000}, {name=i, param1=000},

{name=b, param1=255}, {name=b, param1=255}, {name=b, param1=255}, {name=b, param1=255}, {name=b, param1=255},
{name=i, param1=000}, {name=b, param1=100}, {name=b, param1=255}, {name=b, param1=100}, {name=i, param1=000},
{name=i, param1=000}, {name=i, param1=000}, {name=i, param1=000}, {name=i, param1=000}, {name=i, param1=000},

{name=b, param1=100}, {name=b, param1=255}, {name=b, param1=255}, {name=b, param1=255}, {name=b, param1=100},
{name=i, param1=000}, {name=i, param1=000}, {name=i, param1=000}, {name=i, param1=000}, {name=i, param1=000},
{name=i, param1=000}, {name=i, param1=000}, {name=i, param1=000}, {name=i, param1=000}, {name=i, param1=000},

	},
	yslice_prob = {
		{ypos=1, prob=127},
	},
}
